package exception3;

public class Throw02_361p {

	public static void doIt(String[] s, int i) throws ArrayIndexOutOfBoundsException{
		
		//내부가 인덱스 조회이므로, 언제든지 ArrayIndexOutOfBoundsException 발생이 가능한 상황
		System.out.println(s[i]);
	}
	public static void main(String[] args) {
		
		// 특정 메소드 영역에서 발생하는 코드는 엄밀히 말하면 
		// try블럭 외부의 예외발생으로 간주된다.
		// 따라서, 개념적으로는 try블럭 밖에 있지만 
		// 실제로는 try블럭에 속한것처럼 처리하기 위해
		// throws를 사용자 정의 메소드 뒤에 붙여준다.
		
		String[] greetings = {"Hello", "안녕", "니하오", "신짜오"};
		int i = (int)(Math.random()*5); // 정수 0 1 2 3 4
		
	    try {
	    	doIt(greetings, i);
	    }
	    catch (Exception e){
	    	System.out.println("FUCK");
	    }
		

}
